INFO:django.utils.autoreload:C:\Users\yehwon\Desktop\KiwoomHTS\KiwoomHTS\urls.py changed, reloading.
INFO:django.utils.autoreload:C:\Users\yehwon\Desktop\KiwoomHTS\KiwoomHTS\urls.py changed, reloading.
WARNING:django.security.csrf:Forbidden (CSRF cookie not set.): /stock/current/
WARNING:django.security.csrf:Forbidden (CSRF cookie not set.): /stock/current/
INFO:django.utils.autoreload:C:\Users\yehwon\Desktop\KiwoomHTS\stock\urls.py changed, reloading.
ERROR:django.request:Internal Server Error: /stock/favorite/
Traceback (most recent call last):
  File "C:\Anaconda\envs\py38_32\lib\site-packages\django\core\handlers\exception.py", line 47, in inner
    response = get_response(request)
  File "C:\Anaconda\envs\py38_32\lib\site-packages\django\core\handlers\base.py", line 181, in _get_response
    response = wrapped_callback(request, *callback_args, **callback_kwargs)
  File "C:\Anaconda\envs\py38_32\lib\site-packages\django\views\decorators\csrf.py", line 54, in wrapped_view
    return view_func(*args, **kwargs)
  File "C:\Anaconda\envs\py38_32\lib\site-packages\django\views\generic\base.py", line 70, in view
    return self.dispatch(request, *args, **kwargs)
  File "C:\Anaconda\envs\py38_32\lib\site-packages\rest_framework\views.py", line 509, in dispatch
    response = self.handle_exception(exc)
  File "C:\Anaconda\envs\py38_32\lib\site-packages\rest_framework\views.py", line 469, in handle_exception
    self.raise_uncaught_exception(exc)
  File "C:\Anaconda\envs\py38_32\lib\site-packages\rest_framework\views.py", line 480, in raise_uncaught_exception
    raise exc
  File "C:\Anaconda\envs\py38_32\lib\site-packages\rest_framework\views.py", line 506, in dispatch
    response = handler(request, *args, **kwargs)
  File "C:\Anaconda\envs\py38_32\lib\site-packages\rest_framework\decorators.py", line 50, in handler
    return func(*args, **kwargs)
  File "C:\Users\yehwon\Desktop\KiwoomHTS\stock\views.py", line 44, in favorite_stock
    data = df.to_json(orient="records", force_ascii=False)
AttributeError: 'int' object has no attribute 'to_json'
INFO:django.utils.autoreload:C:\Users\yehwon\Desktop\KiwoomHTS\stock\views.py changed, reloading.
INFO:django.utils.autoreload:C:\Users\yehwon\Desktop\KiwoomHTS\stock\views.py changed, reloading.
INFO:django.utils.autoreload:C:\Users\yehwon\Desktop\KiwoomHTS\stock\views.py changed, reloading.
INFO:django.utils.autoreload:C:\Users\yehwon\Desktop\KiwoomHTS\stock\views.py changed, reloading.
INFO:django.utils.autoreload:C:\Users\yehwon\Desktop\KiwoomHTS\stock\views.py changed, reloading.
INFO:django.utils.autoreload:C:\Users\yehwon\Desktop\KiwoomHTS\stock\views.py changed, reloading.
INFO:django.utils.autoreload:C:\Anaconda\envs\py38_32\Lib\site-packages\pykiwoom\kiwoom.py changed, reloading.
INFO:django.utils.autoreload:C:\Anaconda\envs\py38_32\Lib\site-packages\pykiwoom\kiwoom.py changed, reloading.
INFO:django.utils.autoreload:C:\Users\yehwon\Desktop\KiwoomHTS\stock\views.py changed, reloading.
INFO:django.utils.autoreload:C:\Users\yehwon\Desktop\KiwoomHTS\stock\views.py changed, reloading.
INFO:django.utils.autoreload:C:\Anaconda\envs\py38_32\Lib\site-packages\pykiwoom\kiwoom.py changed, reloading.
ERROR:django.request:Internal Server Error: /user/
Traceback (most recent call last):
  File "C:\Anaconda\envs\py38_32\lib\site-packages\pykiwoom\kiwoom.py", line 17, in __call__
    return cls._instance
AttributeError: type object 'Kiwoom' has no attribute '_instance'

During handling of the above exception, another exception occurred:

Traceback (most recent call last):
  File "C:\Anaconda\envs\py38_32\lib\site-packages\django\core\handlers\exception.py", line 47, in inner
    response = get_response(request)
  File "C:\Anaconda\envs\py38_32\lib\site-packages\django\core\handlers\base.py", line 181, in _get_response
    response = wrapped_callback(request, *callback_args, **callback_kwargs)
  File "C:\Anaconda\envs\py38_32\lib\site-packages\django\views\decorators\csrf.py", line 54, in wrapped_view
    return view_func(*args, **kwargs)
  File "C:\Anaconda\envs\py38_32\lib\site-packages\django\views\generic\base.py", line 70, in view
    return self.dispatch(request, *args, **kwargs)
  File "C:\Anaconda\envs\py38_32\lib\site-packages\rest_framework\views.py", line 509, in dispatch
    response = self.handle_exception(exc)
  File "C:\Anaconda\envs\py38_32\lib\site-packages\rest_framework\views.py", line 469, in handle_exception
    self.raise_uncaught_exception(exc)
  File "C:\Anaconda\envs\py38_32\lib\site-packages\rest_framework\views.py", line 480, in raise_uncaught_exception
    raise exc
  File "C:\Anaconda\envs\py38_32\lib\site-packages\rest_framework\views.py", line 506, in dispatch
    response = handler(request, *args, **kwargs)
  File "C:\Anaconda\envs\py38_32\lib\site-packages\rest_framework\decorators.py", line 50, in handler
    return func(*args, **kwargs)
  File "C:\Users\yehwon\Desktop\KiwoomHTS\user\views.py", line 12, in current_user
    kiwoom = Kiwoom()
  File "C:\Anaconda\envs\py38_32\lib\site-packages\pykiwoom\kiwoom.py", line 19, in __call__
    cls._instance = super().__call__(*args, **kwargs)
  File "C:\Anaconda\envs\py38_32\lib\site-packages\pykiwoom\kiwoom.py", line 35, in __init__
    self._set_signals_slots()
  File "C:\Anaconda\envs\py38_32\lib\site-packages\pykiwoom\kiwoom.py", line 100, in _set_signals_slots
    self.ocx.OnEventConnect.connect(self._handler_login)
AttributeError: 'QAxWidget' object has no attribute 'OnEventConnect'
INFO:django.utils.autoreload:C:\Users\yehwon\Desktop\KiwoomHTS\stock\views.py changed, reloading.
INFO:django.utils.autoreload:C:\Users\yehwon\Desktop\KiwoomHTS\stock\views.py changed, reloading.
INFO:django.utils.autoreload:C:\Users\yehwon\Desktop\KiwoomHTS\stock\views.py changed, reloading.
INFO:django.utils.autoreload:C:\Users\yehwon\Desktop\KiwoomHTS\stock\views.py changed, reloading.
INFO:django.utils.autoreload:C:\Users\yehwon\Desktop\KiwoomHTS\stock\views.py changed, reloading.
ERROR:django.request:Internal Server Error: /stock/current/
Traceback (most recent call last):
  File "C:\Anaconda\envs\py38_32\lib\site-packages\django\core\handlers\exception.py", line 47, in inner
    response = get_response(request)
  File "C:\Anaconda\envs\py38_32\lib\site-packages\django\core\handlers\base.py", line 181, in _get_response
    response = wrapped_callback(request, *callback_args, **callback_kwargs)
  File "C:\Anaconda\envs\py38_32\lib\site-packages\django\views\decorators\csrf.py", line 54, in wrapped_view
    return view_func(*args, **kwargs)
  File "C:\Anaconda\envs\py38_32\lib\site-packages\django\views\generic\base.py", line 70, in view
    return self.dispatch(request, *args, **kwargs)
  File "C:\Anaconda\envs\py38_32\lib\site-packages\rest_framework\views.py", line 509, in dispatch
    response = self.handle_exception(exc)
  File "C:\Anaconda\envs\py38_32\lib\site-packages\rest_framework\views.py", line 469, in handle_exception
    self.raise_uncaught_exception(exc)
  File "C:\Anaconda\envs\py38_32\lib\site-packages\rest_framework\views.py", line 480, in raise_uncaught_exception
    raise exc
  File "C:\Anaconda\envs\py38_32\lib\site-packages\rest_framework\views.py", line 506, in dispatch
    response = handler(request, *args, **kwargs)
  File "C:\Anaconda\envs\py38_32\lib\site-packages\rest_framework\decorators.py", line 50, in handler
    return func(*args, **kwargs)
  File "C:\Users\yehwon\Desktop\KiwoomHTS\stock\views.py", line 23, in current_stock
    kiwoom.GetCommData()
TypeError: GetCommData() missing 4 required positional arguments: 'trcode', 'rqname', 'index', and 'item'
INFO:django.utils.autoreload:C:\Users\yehwon\Desktop\KiwoomHTS\stock\views.py changed, reloading.
INFO:django.utils.autoreload:C:\Users\yehwon\Desktop\KiwoomHTS\stock\views.py changed, reloading.
INFO:django.utils.autoreload:C:\Users\yehwon\Desktop\KiwoomHTS\stock\views.py changed, reloading.
INFO:django.utils.autoreload:C:\Users\yehwon\Desktop\KiwoomHTS\stock\views.py changed, reloading.
INFO:django.utils.autoreload:C:\Users\yehwon\Desktop\KiwoomHTS\stock\views.py changed, reloading.
ERROR:django.request:Internal Server Error: /stock/current/
Traceback (most recent call last):
  File "C:\Anaconda\envs\py38_32\lib\site-packages\django\core\handlers\exception.py", line 47, in inner
    response = get_response(request)
  File "C:\Anaconda\envs\py38_32\lib\site-packages\django\core\handlers\base.py", line 181, in _get_response
    response = wrapped_callback(request, *callback_args, **callback_kwargs)
  File "C:\Anaconda\envs\py38_32\lib\site-packages\django\views\decorators\csrf.py", line 54, in wrapped_view
    return view_func(*args, **kwargs)
  File "C:\Anaconda\envs\py38_32\lib\site-packages\django\views\generic\base.py", line 70, in view
    return self.dispatch(request, *args, **kwargs)
  File "C:\Anaconda\envs\py38_32\lib\site-packages\rest_framework\views.py", line 509, in dispatch
    response = self.handle_exception(exc)
  File "C:\Anaconda\envs\py38_32\lib\site-packages\rest_framework\views.py", line 469, in handle_exception
    self.raise_uncaught_exception(exc)
  File "C:\Anaconda\envs\py38_32\lib\site-packages\rest_framework\views.py", line 480, in raise_uncaught_exception
    raise exc
  File "C:\Anaconda\envs\py38_32\lib\site-packages\rest_framework\views.py", line 506, in dispatch
    response = handler(request, *args, **kwargs)
  File "C:\Anaconda\envs\py38_32\lib\site-packages\rest_framework\decorators.py", line 50, in handler
    return func(*args, **kwargs)
  File "C:\Users\yehwon\Desktop\KiwoomHTS\stock\views.py", line 29, in current_stock
    return Response(json.dumps(df))
  File "C:\Anaconda\envs\py38_32\lib\json\__init__.py", line 231, in dumps
    return _default_encoder.encode(obj)
  File "C:\Anaconda\envs\py38_32\lib\json\encoder.py", line 199, in encode
    chunks = self.iterencode(o, _one_shot=True)
  File "C:\Anaconda\envs\py38_32\lib\json\encoder.py", line 257, in iterencode
    return _iterencode(o, 0)
  File "C:\Anaconda\envs\py38_32\lib\json\encoder.py", line 179, in default
    raise TypeError(f'Object of type {o.__class__.__name__} '
TypeError: Object of type DataFrame is not JSON serializable
INFO:django.utils.autoreload:C:\Users\yehwon\Desktop\KiwoomHTS\stock\views.py changed, reloading.
INFO:django.utils.autoreload:C:\Users\yehwon\Desktop\KiwoomHTS\stock\views.py changed, reloading.
INFO:django.utils.autoreload:C:\Users\yehwon\Desktop\KiwoomHTS\stock\views.py changed, reloading.
ERROR:django.request:Internal Server Error: /stock/current/
Traceback (most recent call last):
  File "C:\Anaconda\envs\py38_32\lib\site-packages\django\core\handlers\exception.py", line 47, in inner
    response = get_response(request)
  File "C:\Anaconda\envs\py38_32\lib\site-packages\django\core\handlers\base.py", line 181, in _get_response
    response = wrapped_callback(request, *callback_args, **callback_kwargs)
  File "C:\Anaconda\envs\py38_32\lib\site-packages\django\views\decorators\csrf.py", line 54, in wrapped_view
    return view_func(*args, **kwargs)
  File "C:\Anaconda\envs\py38_32\lib\site-packages\django\views\generic\base.py", line 70, in view
    return self.dispatch(request, *args, **kwargs)
  File "C:\Anaconda\envs\py38_32\lib\site-packages\rest_framework\views.py", line 509, in dispatch
    response = self.handle_exception(exc)
  File "C:\Anaconda\envs\py38_32\lib\site-packages\rest_framework\views.py", line 469, in handle_exception
    self.raise_uncaught_exception(exc)
  File "C:\Anaconda\envs\py38_32\lib\site-packages\rest_framework\views.py", line 480, in raise_uncaught_exception
    raise exc
  File "C:\Anaconda\envs\py38_32\lib\site-packages\rest_framework\views.py", line 506, in dispatch
    response = handler(request, *args, **kwargs)
  File "C:\Anaconda\envs\py38_32\lib\site-packages\rest_framework\decorators.py", line 50, in handler
    return func(*args, **kwargs)
  File "C:\Users\yehwon\Desktop\KiwoomHTS\stock\views.py", line 27, in current_stock
    data = StockSerializer(stock_object).data
  File "C:\Anaconda\envs\py38_32\lib\site-packages\rest_framework\serializers.py", line 548, in data
    ret = super().data
  File "C:\Anaconda\envs\py38_32\lib\site-packages\rest_framework\serializers.py", line 246, in data
    self._data = self.to_representation(self.instance)
  File "C:\Anaconda\envs\py38_32\lib\site-packages\rest_framework\serializers.py", line 515, in to_representation
    ret[field.field_name] = field.to_representation(attribute)
  File "C:\Anaconda\envs\py38_32\lib\site-packages\rest_framework\fields.py", line 963, in to_representation
    return int(value)
TypeError: int() argument must be a string, a bytes-like object or a number, not 'DataFrame'
INFO:django.utils.autoreload:C:\Anaconda\envs\py38_32\Lib\site-packages\pykiwoom\kiwoom.py changed, reloading.
INFO:django.utils.autoreload:C:\Anaconda\envs\py38_32\Lib\site-packages\pykiwoom\kiwoom.py changed, reloading.
INFO:django.utils.autoreload:C:\Anaconda\envs\py38_32\Lib\site-packages\pykiwoom\kiwoom.py changed, reloading.
INFO:django.utils.autoreload:C:\Users\yehwon\Desktop\KiwoomHTS\stock\views.py changed, reloading.
INFO:django.utils.autoreload:C:\Anaconda\envs\py38_32\Lib\site-packages\pykiwoom\kiwoom.py changed, reloading.
INFO:django.utils.autoreload:C:\Anaconda\envs\py38_32\Lib\site-packages\pykiwoom\kiwoom.py changed, reloading.
INFO:django.utils.autoreload:C:\Anaconda\envs\py38_32\Lib\site-packages\pykiwoom\kiwoom.py changed, reloading.
